<?xml version="1.0" ?>
<mujoco model="X5">
    <compiler angle="radian" meshdir="meshes"/>
    
    <!-- 执行器定义 -->
    <actuator>
        <motor ctrllimited="true" ctrlrange="-100.0 100.0" joint="joint1" name="torq_j1"/>
        <motor ctrllimited="true" ctrlrange="-100.0 100.0" joint="joint2" name="torq_j2"/>
        <motor ctrllimited="true" ctrlrange="-30.0 30.0" joint="joint3" name="torq_j3"/>
        <motor ctrllimited="true" ctrlrange="-30.0 30.0" joint="joint4" name="torq_j4"/>
        <motor ctrllimited="true" ctrlrange="-100.0 100.0" joint="joint5" name="torq_j5"/>
        <motor ctrllimited="true" ctrlrange="-100.0 100.0" joint="joint6" name="torq_j6"/>
    </actuator>

    <!-- 资源定义 -->
    <asset>
        <mesh name="base_link" file="base_link.STL"/>
        <mesh name="link1" file="link1.STL"/>
        <mesh name="link2" file="link2.STL"/>
        <mesh name="link3" file="link3.STL"/>
        <mesh name="link4" file="link4.STL"/>
        <mesh name="link5" file="link5.STL"/>
        <mesh name="link6" file="link6.STL"/>
        
        <!-- 材质定义 -->
        <material name="gray" rgba="0.75294 0.75294 0.75294 1"/>
        <material name="light_gray" rgba="0.89804 0.91765 0.92941 1"/>
    </asset>

    <!-- 机器人主体结构 -->
    <worldbody>
        <body name="base_link" pos="0 0 0">
            <inertial pos="-3.764e-5 0.00006519 0.03037877" mass="0.428" 
                     diaginertia="0.00060728 0.00060832 0.0001917"/>
            <geom type="mesh" mesh="base_link" material="gray"/>
            
            <body name="link1" pos="0 0 0.0603">
                <joint name="joint1" type="hinge" axis="0 0 1" limited="true" 
                       range="-10 10"/>
                <inertial pos="0.00571213 0.0002547 0.01750661" mass="0.064"
                         diaginertia="0.00008 0.00003 0.00007"/>
                <geom type="mesh" mesh="link1" material="gray"/>
                
                <body name="link2" pos="0.02 0 0.0402">
                    <joint name="joint2" type="hinge" axis="0 1 0" limited="true"
                           range="0 3.14"/>
                    <inertial pos="-0.13225701 0.00072373 4.274e-5" mass="1.165"
                             diaginertia="0.00057063 0.03669927 0.03683489"/>
                    <geom type="mesh" mesh="link2" material="gray"/>
                    
                    <body name="link3" pos="-0.264 0 0" quat="0 1 0 0">
                        <joint name="joint3" type="hinge" axis="0 1 0" limited="true"
                               range="0 3.14"/>
                        <inertial pos="0.19096098 0.00069065 -0.05342172" mass="0.546"
                                 diaginertia="0.00178249 0.02486615 0.02329476"/>
                        <geom type="mesh" mesh="link3" material="gray"/>
                        <geom type="cylinder" size="0.02 0.075" pos="0.15 0 -0.055" 
                              quat="0.707107 0 0.707107 0"/>
                        
                        <body name="link4" pos="0.245 0 -0.056">
                            <joint name="joint4" type="hinge" axis="0 1 0" limited="true"
                                   range="-1.57079632679 1.57079632679"/>
                            <inertial pos="0.03092317 0.0066107 -0.03138504" mass="0.080971"
                                     diaginertia="0.00017832 0.00021182 0.00011328"/>
                            <geom type="mesh" mesh="link4" material="light_gray"/>
                            <geom type="cylinder" size="0.025 0.025" pos="0.06575 -0.001 -0.02"/>
                            
                            <body name="link5" pos="0.06575 -0.001 -0.0825">
                                <joint name="joint5" type="hinge" axis="0 0 1" limited="true"
                                       range="-1.67 1.67"/>
                                <inertial pos="0.0040681 0.00000885 0.05120675" mass="0.655"
                                         diaginertia="0.00254972 0.00255018 0.00026961"/>
                                <geom type="mesh" mesh="link5" material="gray"/>
                                <geom type="cylinder" size="0.02 0.0125" pos="0.055 0 0.083"
                                      quat="0.707107 0 0.707107 0"/>
                                
                                <body name="link6" pos="0.02845 0 0.0825" quat="0 1 0 0">
                                    <joint name="joint6" type="hinge" axis="1 0 0" limited="true"
                                           range="-1.57 1.57"/>
                                    <inertial pos="0.05435277 0 0" mass="0.581"
                                             diaginertia="0.00029 0.00028 0.00045"/>
                                    <geom type="mesh" mesh="link6" material="light_gray"/>
                                    
                                    <body name="eef_link" pos="0.145 0 0">
                                        <site name="ee_site" pos="0 0 0" size="0.01"/>
                                        <site name="ee_x" pos="0.1 0 0" size="0.005 0.1" rgba="1 0 0 0.3"/>
                                        <site name="ee_y" pos="0 0.1 0" size="0.005 0.1" rgba="0 1 0 0.3"/>
                                        <site name="ee_z" pos="0 0 0.1" size="0.005 0.1" rgba="0 0 1 0.3"/>
                                    </body>
                                </body>
                            </body>
                        </body>
                    </body>
                </body>
            </body>
        </body>
    </worldbody>
</mujoco>